Workbook

Sheet Sheet1
A1: kbli1 | B1: kbli5 | C1: judul | D1: contoh_usaha | E1: kata_kunci | F1: kategori | G1: digital_hijau | H1: ciri_usaha | I1: proses | J1: bahan_baku | K1: output
A2: A | B2: '01111 | C2: PERTANIAN JAGUNG | D2: #N/A | E2: #N/A | F2: #N/A | G2: #N/A | H2: #N/A | I2: #N/A | J2: #N/A | K2: #N/A
A3: A | B3: '01112 | C3: PERTANIAN SEREALIA SELAIN PADI DAN JAGUNG | D3: #N/A | E3: #N/A | F3: #N/A | G3: #N/A | H3: #N/A | I3: #N/A | J3: #N/A | K3: #N/A
A4: A | B4: '01113 | C4: PERTANIAN KEDELAI | D4: #N/A | E4: #N/A | F4: #N/A | G4: #N/A | H4: #N/A | I4: #N/A | J4: #N/A | K4: #N/A
A5: A | B5: '01114 | C5: PERTANIAN KACANG TANAH | D5: #N/A | E5: #N/A | F5: #N/A | G5: #N/A | H5: #N/A | I5: #N/A | J5: #N/A | K5: #N/A
A6: A | B6: '01115 | C6: PERTANIAN KACANG HIJAU | D6: #N/A | E6: #N/A | F6: #N/A | G6: #N/A | H6: #N/A | I6: #N/A | J6: #N/A | K6: #N/A
A7: A | B7: '01116 | C7: PERTANIAN ANEKA KACANG SELAIN KEDELAI, KACANG TANAH, DAN | D7: #N/A | E7: #N/A | F7: #N/A | G7: #N/A | H7: #N/A | I7: #N/A | J7: #N/A | K7: #N/A
A8: A | B8: '01117 | C8: PERTANIAN BIJI-BIJIAN PENGHASIL MINYAK MAKAN | D8: #N/A | E8: #N/A | F8: #N/A | G8: #N/A | H8: #N/A | I8: #N/A | J8: #N/A | K8: #N/A
A9: A | B9: '01118 | C9: PERTANIAN BIJI-BIJIAN PENGHASIL MINYAK SELAIN MINYAK MAKAN | D9: #N/A | E9: #N/A | F9: #N/A | G9: #N/A | H9: #N/A | I9: #N/A | J9: #N/A | K9: #N/A
A10: A | B10: '01121 | C10: PERTANIAN PADI HIBRIDA | D10: #N/A | E10: #N/A | F10: #N/A | G10: #N/A | H10: #N/A | I10: #N/A | J10: #N/A | K10: #N/A
A11: A | B11: '01122 | C11: PERTANIAN PADI INBRIDA | D11: #N/A | E11: #N/A | F11: #N/A | G11: #N/A | H11: #N/A | I11: #N/A | J11: #N/A | K11: #N/A
A12: A | B12: '01131 | C12: PERTANIAN SAYURAN DAUN | D12: #N/A | E12: #N/A | F12: #N/A | G12: #N/A | H12: #N/A | I12: #N/A | J12: #N/A | K12: #N/A
A13: A | B13: '01132 | C13: PERTANIAN BUAH SEMUSIM | D13: #N/A | E13: #N/A | F13: #N/A | G13: #N/A | H13: #N/A | I13: #N/A | J13: #N/A | K13: #N/A
... A126: B | B126: '05200 | C126: PERTAMBANGAN LIGNIT | D126: #N/A | E126: #N/A | F126: #N/A | G126: #N/A | H126: #N/A | I126: #N/A | J126: #N/A | K126: #N/A
A127: B | B127: '06100 | C127: PERTAMBANGAN MINYAK BUMI | D127: #N/A | E127: #N/A | F127: #N/A | G127: Ekonomi Hijau; | H127: #N/A | I127: #N/A | J127: #N/A | K127: #N/A
A128: B | B128: '06201 | C128: PERTAMBANGAN GAS ALAM | D128: #N/A | E128: #N/A | F128: #N/A | G128: Ekonomi Hijau; | H128: #N/A | I128: #N/A | J128: #N/A | K128: #N/A
A129: B | B129: '06202 | C129: PENGUSAHAAN TENAGA PANAS BUMI | D129: #N/A | E129: #N/A | F129: #N/A | G129: Ekonomi Hijau; | H129: #N/A | I129: #N/A | J129: #N/A | K129: #N/A
A130: B | B130: '07101 | C130: PERTAMBANGAN PASIR BESI | D130: #N/A | E130: #N/A | F130: #N/A | G130: Ekonomi Hijau; | H130: #N/A | I130: #N/A | J130: #N/A | K130: #N/A
A131: B | B131: '07102 | C131: PERTAMBANGAN BIJIH BESI | D131: #N/A | E131: #N/A | F131: #N/A | G131: Ekonomi Hijau; | H131: #N/A | I131: #N/A | J131: #N/A | K131: #N/A
A132: B | B132: '07210 | C132: PERTAMBANGAN BIJIH URANIUM DAN TORIUM | D132: #N/A | E132: #N/A | F132: #N/A | G132: Ekonomi Hijau; | H132: #N/A | I132: #N/A | J132: #N/A | K132: #N/A
A133: B | B133: '07221 | C133: PERTAMBANGAN EMAS DAN PERAK | D133: #N/A | E133: #N/A | F133: #N/A | G133: Ekonomi Hijau; | H133: #N/A | I133: #N/A | J133: #N/A | K133: #N/A
A134: B | B134: '07229 | C134: PERTAMBANGAN BIJIH LOGAM MULIA LAINNYA | D134: #N/A | E134: #N/A | F134: #N/A | G134: Ekonomi Hijau; | H134: #N/A | I134: #N/A | J134: #N/A | K134: #N/A
A135: B | B135: '07291 | C135: PERTAMBANGAN BIJIH TIMAH | D135: #N/A | E135: #N/A | F135: #N/A | G135: Ekonomi Hijau; | H135: #N/A | I135: #N/A | J135: #N/A | K135: #N/A
A136: B | B136: '07292 | C136: PERTAMBANGAN BIJIH TIMAH HITAM | D136: #N/A | E136: #N/A | F136: #N/A | G136: Ekonomi Hijau; | H136: #N/A | I136: #N/A | J136: #N/A | K136: #N/A
A137: B | B137: '07293 | C137: PERTAMBANGAN BIJIH BAUKSIT | D137: #N/A | E137: #N/A | F137: #N/A | G137: Ekonomi Hijau; | H137: #N/A | I137: #N/A | J137: #N/A | K137: #N/A
A138: B | B138: '07294 | C138: PERTAMBANGAN BIJIH TEMBAGA | D138: #N/A | E138: #N/A | F138: #N/A | G138: Ekonomi Hijau; | H138: #N/A | I138: #N/A | J138: #N/A | K138: #N/A
A139: B | B139: '07295 | C139: PERTAMBANGAN BIJIH NIKEL | D139: #N/A | E139: #N/A | F139: #N/A | G139: Ekonomi Hijau; | H139: #N/A | I139: #N/A | J139: #N/A | K139: #N/A
A140: B | B140: '07296 | C140: PERTAMBANGAN BIJIH MANGAN | D140: #N/A | E140: #N/A | F140: #N/A | G140: #N/A | H140: #N/A | I140: #N/A | J140: #N/A | K140: #N/A
A141: B | B141: '07299 | C141: PERTAMBANGAN BAHAN GALIAN LAINNYA YANG TIDAK MENGANDUNG | D141: #N/A | E141: #N/A | F141: #N/A | G141: #N/A | H141: #N/A | I141: #N/A | J141: #N/A | K141: #N/A
A142: B | B142: '08101 | C142: PENGGALIAN BATU HIAS DAN BATU BANGUNAN | D142: #N/A | E142: #N/A | F142: #N/A | G142: #N/A | H142: #N/A | I142: #N/A | J142: #N/A | K142: #N/A
A143: B | B143: '08102 | C143: PENGGALIAN BATU KAPUR/GAMPING | D143: #N/A | E143: #N/A | F143: #N/A | G143: #N/A | H143: #N/A | I143: #N/A | J143: #N/A | K143: #N/A
A144: B | B144: '08103 | C144: PENGGALIAN KERIKIL/SIRTU | D144: #N/A | E144: #N/A | F144: #N/A | G144: #N/A | H144: #N/A | I144: #N/A | J144: #N/A | K144: #N/A
A145: B | B145: '08104 | C145: PENGGALIAN PASIR | D145: #N/A | E145: #N/A | F145: #N/A | G145: #N/A | H145: #N/A | I145: #N/A | J145: #N/A | K145: #N/A
A146: B | B146: '08105 | C146: PENGGALIAN TANAH DAN TANAH LIAT | D146: #N/A | E146: #N/A | F146: #N/A | G146: #N/A | H146: #N/A | I146: #N/A | J146: #N/A | K146: #N/A
A147: B | B147: '08106 | C147: PENGGALIAN GIPS | D147: #N/A | E147: #N/A | F147: #N/A | G147: #N/A | H147: #N/A | I147: #N/A | J147: #N/A | K147: #N/A
A148: B | B148: '08107 | C148: PENGGALIAN TRAS | D148: #N/A | E148: #N/A | F148: #N/A | G148: #N/A | H148: #N/A | I148: #N/A | J148: #N/A | K148: #N/A
A149: B | B149: '08108 | C149: PENGGALIAN BATU APUNG | D149: #N/A | E149: #N/A | F149: #N/A | G149: #N/A | H149: #N/A | I149: #N/A | J149: #N/A | K149: #N/A
A150: B | B150: '08109 | C150: PENGGALIAN BATU, PASIR, DAN TANAH LIAT LAINNYA | D150: #N/A | E150: #N/A | F150: #N/A | G150: #N/A | H150: #N/A | I150: #N/A | J150: #N/A | K150: #N/A
A151: B | B151: '08911 | C151: PERTAMBANGAN BELERANG | D151: #N/A | E151: #N/A | F151: #N/A | G151: #N/A | H151: #N/A | I151: #N/A | J151: #N/A | K151: #N/A
... A167: B | B167: '09900 | C167: AKTIVITAS PENUNJANG PERTAMBANGAN DAN PENGGALIAN LAINNYA | D167: #N/A | E167: #N/A | F167: #N/A | G167: #N/A | H167: #N/A | I167: #N/A | J167: #N/A | K167: #N/A
...

Sheet master
A1: kbli5 | B1: judul | C1: kbli1 | D1: DIGITAL (INDUSTRY) | E1: GREEN (ECONOMY)
A2: '01111 | B2: PERTANIAN JAGUNG | C2: A
A3: '01112 | B3: PERTANIAN SEREALIA SELAIN PADI DAN JAGUNG | C3: A
A4: '01113 | B4: PERTANIAN KEDELAI | C4: A
A5: '01114 | B5: PERTANIAN KACANG TANAH | C5: A
A6: '01115 | B6: PERTANIAN KACANG HIJAU | C6: A
A7: '01116 | B7: PERTANIAN ANEKA KACANG SELAIN KEDELAI, KACANG TANAH, DAN | C7: A
A8: '01117 | B8: PERTANIAN BIJI-BIJIAN PENGHASIL MINYAK MAKAN | C8: A
A9: '01118 | B9: PERTANIAN BIJI-BIJIAN PENGHASIL MINYAK SELAIN MINYAK MAKAN | C9: A
A10: '01121 | B10: PERTANIAN PADI HIBRIDA | C10: A
A11: '01122 | B11: PERTANIAN PADI INBRIDA | C11: A
A12: '01131 | B12: PERTANIAN SAYURAN DAUN | C12: A
A13: '01132 | B13: PERTANIAN BUAH SEMUSIM | C13: A
... A126: '05200 | B126: PERTAMBANGAN LIGNIT | C126: B
A127: '06100 | B127: PERTAMBANGAN MINYAK BUMI | C127: B | E127: Ekonomi Hijau;
A128: '06201 | B128: PERTAMBANGAN GAS ALAM | C128: B
A129: '06202 | B129: PENGUSAHAAN TENAGA PANAS BUMI | C129: B
A130: '07101 | B130: PERTAMBANGAN PASIR BESI | C130: B
A131: '07102 | B131: PERTAMBANGAN BIJIH BESI | C131: B
A132: '07210 | B132: PERTAMBANGAN BIJIH URANIUM DAN TORIUM | C132: B
A133: '07221 | B133: PERTAMBANGAN EMAS DAN PERAK | C133: B
A134: '07229 | B134: PERTAMBANGAN BIJIH LOGAM MULIA LAINNYA | C134: B
A135: '07291 | B135: PERTAMBANGAN BIJIH TIMAH | C135: B
A136: '07292 | B136: PERTAMBANGAN BIJIH TIMAH HITAM | C136: B
A137: '07293 | B137: PERTAMBANGAN BIJIH BAUKSIT | C137: B
A138: '07294 | B138: PERTAMBANGAN BIJIH TEMBAGA | C138: B
A139: '07295 | B139: PERTAMBANGAN BIJIH NIKEL | C139: B
... A167: '09900 | B167: AKTIVITAS PENUNJANG PERTAMBANGAN DAN PENGGALIAN LAINNYA | C167: B
A168: 10111 | B168: KEGIATAN RUMAH POTONG HEWAN RUMINANSIA | C168: C
A169: 10112 | B169: KEGIATAN RUMAH POTONG BABI | C169: C
A170: 10113 | B170: KEGIATAN RUMAH POTONG UNGGAS | C170: C
A171: 10119 | B171: KEGIATAN RUMAH POTONG HEWAN LAINNYA | C171: C
A172: 10120 | B172: PENGOLAHAN DAN PENGAWETAN DAGING DAN PRODUK DAGING | C172: C
A173: 10211 | B173: PENGOLAHAN DAN PENGAWETAN IKAN DENGAN PENGGARAMAN ATAU | C173: C
A174: 10212 | B174: PENGOLAHAN DAN PENGAWETAN IKAN DENGAN PENGASAPAN ATAU | C174: C
A175: 10213 | B175: PENGOLAHAN DAN PENGAWETAN IKAN DENGAN PEMBEKUAN | C175: C
A176: 10214 | B176: PENGOLAHAN DAN PENGAWETAN IKAN DENGAN PEMINDANGAN | C176: C
A177: 10215 | B177: PENGOLAHAN DAN PENGAWETAN IKAN DENGAN FERMENTASI | C177: C
A178: 10216 | B178: PENGOLAHAN DAN PENGAWETAN IKAN DENGAN PELUMATAN | C178: C
A179: 10217 | B179: PENGOLAHAN DAN PENGAWETAN IKAN DENGAN PENGALENGAN | C179: C
...

Sheet rapikan_all
A1: kbli1 | B1: kbli5 | C1: judul | D1: contoh_usaha | E1: kata_kunci | F1: kategori | G1: digital_hijau | H1: ciri_usaha | I1: proses | J1: bahan_baku | K1: output
A2: A | B2: '01111 | C2: PERTANIAN JAGUNG | D2: =VLOOKUP(Table13[[#This Row],[kbli5]],Table1[[#All],[kbli5]:[digital_hijau]],3,) -> #N/A | E2: =VLOOKUP(Table13[[#This Row],[kbli5]],kata_kunci!$B:$H,4,FALSE) -> #N/A | F2: =VLOOKUP(Table13[[#This Row],[kbli5]],Table1[[#All],[kbli5]:[digital_hijau]],5,) -> #N/A | G2: =VLOOKUP(Table13[[#This Row],[kbli5]],Table1[[#All],[kbli5]:[digital_hijau]],6,) -> #N/A | H2: =VLOOKUP(Table13[[#This Row],[kbli5]],kata_kunci!$B:$H,3,FALSE) -> #N/A | I2: =VLOOKUP(Table13[[#This Row],[kbli5]],kata_kunci!$B:$H,5,FALSE) -> #N/A | J2: =VLOOKUP(Table13[[#This Row],[kbli5]],kata_kunci!$B:$H,6,FALSE) -> #N/A | K2: =VLOOKUP(Table13[[#This Row],[kbli5]],kata_kunci!$B:$H,7,FALSE) -> #N/A
A3: A | B3: '01112 | C3: PERTANIAN SEREALIA SELAIN PADI DAN JAGUNG | D3: =VLOOKUP(Table13[[#This Row],[kbli5]],Table1[[#All],[kbli5]:[digital_hijau]],3,) -> #N/A | E3: =VLOOKUP(Table13[[#This Row],[kbli5]],kata_kunci!$B:$H,4,FALSE) -> #N/A | F3: =VLOOKUP(Table13[[#This Row],[kbli5]],Table1[[#All],[kbli5]:[digital_hijau]],5,) -> #N/A | G3: =VLOOKUP(Table13[[#This Row],[kbli5]],Table1[[#All],[kbli5]:[digital_hijau]],6,) -> #N/A | H3: =VLOOKUP(Table13[[#This Row],[kbli5]],kata_kunci!$B:$H,3,FALSE) -> #N/A | I3: =VLOOKUP(Table13[[#This Row],[kbli5]],kata_kunci!$B:$H,5,FALSE) -> #N/A | J3: =VLOOKUP(Table13[[#This Row],[kbli5]],kata_kunci!$B:$H,6,FALSE) -> #N/A | K3: =VLOOKUP(Table13[[#This Row],[kbli5]],kata_kunci!$B:$H,7,FALSE) -> #N/A
A4: A | B4: '01113 | C4: PERTANIAN KEDELAI | D4: =VLOOKUP(Table13[[#This Row],[kbli5]],Table1[[#All],[kbli5]:[digital_hijau]],3,) -> #N/A | E4: =VLOOKUP(Table13[[#This Row],[kbli5]],kata_kunci!$B:$H,4,FALSE) -> #N/A | F4: =VLOOKUP(Table13[[#This Row],[kbli5]],Table1[[#All],[kbli5]:[digital_hijau]],5,) -> #N/A | G4: =VLOOKUP(Table13[[#This Row],[kbli5]],Table1[[#All],[kbli5]:[digital_hijau]],6,) -> #N/A | H4: =VLOOKUP(Table13[[#This Row],[kbli5]],kata_kunci!$B:$H,3,FALSE) -> #N/A | I4: =VLOOKUP(Table13[[#This Row],[kbli5]],kata_kunci!$B:$H,5,FALSE) -> #N/A | J4: =VLOOKUP(Table13[[#This Row],[kbli5]],kata_kunci!$B:$H,6,FALSE) -> #N/A | K4: =VLOOKUP(Table13[[#This Row],[kbli5]],kata_kunci!$B:$H,7,FALSE) -> #N/A
A5: A | B5: '01114 | C5: PERTANIAN KACANG TANAH | D5: =VLOOKUP(Table13[[#This Row],[kbli5]],Table1[[#All],[kbli5]:[digital_hijau]],3,) -> #N/A | E5: =VLOOKUP(Table13[[#This Row],[kbli5]],kata_kunci!$B:$H,4,FALSE) -> #N/A | F5: =VLOOKUP(Table13[[#This Row],[kbli5]],Table1[[#All],[kbli5]:[digital_hijau]],5,) -> #N/A | G5: =VLOOKUP(Table13[[#This Row],[kbli5]],Table1[[#All],[kbli5]:[digital_hijau]],6,) -> #N/A | H5: =VLOOKUP(Table13[[#This Row],[kbli5]],kata_kunci!$B:$H,3,FALSE) -> #N/A | I5: =VLOOKUP(Table13[[#This Row],[kbli5]],kata_kunci!$B:$H,5,FALSE) -> #N/A | J5: =VLOOKUP(Table13[[#This Row],[kbli5]],kata_kunci!$B:$H,6,FALSE) -> #N/A | K5: =VLOOKUP(Table13[[#This Row],[kbli5]],kata_kunci!$B:$H,7,FALSE) -> #N/A
A6: A | B6: '01115 | C6: PERTANIAN KACANG HIJAU | D6: =VLOOKUP(Table13[[#This Row],[kbli5]],Table1[[#All],[kbli5]:[digital_hijau]],3,) -> #N/A | E6: =VLOOKUP(Table13[[#This Row],[kbli5]],kata_kunci!$B:$H,4,FALSE) -> #N/A | F6: =VLOOKUP(Table13[[#This Row],[kbli5]],Table1[[#All],[kbli5]:[digital_hijau]],5,) -> #N/A | G6: =VLOOKUP(Table13[[#This Row],[kbli5]],Table1[[#All],[kbli5]:[digital_hijau]],6,) -> #N/A | H6: =VLOOKUP(Table13[[#This Row],[kbli5]],kata_kunci!$B:$H,3,FALSE) -> #N/A | I6: =VLOOKUP(Table13[[#This Row],[kbli5]],kata_kunci!$B:$H,5,FALSE) -> #N/A | J6: =VLOOKUP(Table13[[#This Row],[kbli5]],kata_kunci!$B:$H,6,FALSE) -> #N/A | K6: =VLOOKUP(Table13[[#This Row],[kbli5]],kata_kunci!$B:$H,7,FALSE) -> #N/A
A7: A | B7: '01116 | C7: PERTANIAN ANEKA KACANG SELAIN KEDELAI, KACANG TANAH, DAN | D7: =VLOOKUP(Table13[[#This Row],[kbli5]],Table1[[#All],[kbli5]:[digital_hijau]],3,) -> #N/A | E7: =VLOOKUP(Table13[[#This Row],[kbli5]],kata_kunci!$B:$H,4,FALSE) -> #N/A | F7: =VLOOKUP(Table13[[#This Row],[kbli5]],Table1[[#All],[kbli5]:[digital_hijau]],5,) -> #N/A | G7: =VLOOKUP(Table13[[#This Row],[kbli5]],Table1[[#All],[kbli5]:[digital_hijau]],6,) -> #N/A | H7: =VLOOKUP(Table13[[#This Row],[kbli5]],kata_kunci!$B:$H,3,FALSE) -> #N/A | I7: =VLOOKUP(Table13[[#This Row],[kbli5]],kata_kunci!$B:$H,5,FALSE) -> #N/A | J7: =VLOOKUP(Table13[[#This Row],[kbli5]],kata_kunci!$B:$H,6,FALSE) -> #N/A | K7: =VLOOKUP(Table13[[#This Row],[kbli5]],kata_kunci!$B:$H,7,FALSE) -> #N/A
A8: A | B8: '01117 | C8: PERTANIAN BIJI-BIJIAN PENGHASIL MINYAK MAKAN | D8: =VLOOKUP(Table13[[#This Row],[kbli5]],Table1[[#All],[kbli5]:[digital_hijau]],3,) -> #N/A | E8: =VLOOKUP(Table13[[#This Row],[kbli5]],kata_kunci!$B:$H,4,FALSE) -> #N/A | F8: =VLOOKUP(Table13[[#This Row],[kbli5]],Table1[[#All],[kbli5]:[digital_hijau]],5,) -> #N/A | G8: =VLOOKUP(Table13[[#This Row],[kbli5]],Table1[[#All],[kbli5]:[digital_hijau]],6,) -> #N/A | H8: =VLOOKUP(Table13[[#This Row],[kbli5]],kata_kunci!$B:$H,3,FALSE) -> #N/A | I8: =VLOOKUP(Table13[[#This Row],[kbli5]],kata_kunci!$B:$H,5,FALSE) -> #N/A | J8: =VLOOKUP(Table13[[#This Row],[kbli5]],kata_kunci!$B:$H,6,FALSE) -> #N/A | K8: =VLOOKUP(Table13[[#This Row],[kbli5]],kata_kunci!$B:$H,7,FALSE) -> #N/A
A9: A | B9: '01118 | C9: PERTANIAN BIJI-BIJIAN PENGHASIL MINYAK SELAIN MINYAK MAKAN | D9: =VLOOKUP(Table13[[#This Row],[kbli5]],Table1[[#All],[kbli5]:[digital_hijau]],3,) -> #N/A | E9: =VLOOKUP(Table13[[#This Row],[kbli5]],kata_kunci!$B:$H,4,FALSE) -> #N/A | F9: =VLOOKUP(Table13[[#This Row],[kbli5]],Table1[[#All],[kbli5]:[digital_hijau]],5,) -> #N/A | G9: =VLOOKUP(Table13[[#This Row],[kbli5]],Table1[[#All],[kbli5]:[digital_hijau]],6,) -> #N/A | H9: =VLOOKUP(Table13[[#This Row],[kbli5]],kata_kunci!$B:$H,3,FALSE) -> #N/A | I9: =VLOOKUP(Table13[[#This Row],[kbli5]],kata_kunci!$B:$H,5,FALSE) -> #N/A | J9: =VLOOKUP(Table13[[#This Row],[kbli5]],kata_kunci!$B:$H,6,FALSE) -> #N/A | K9: =VLOOKUP(Table13[[#This Row],[kbli5]],kata_kunci!$B:$H,7,FALSE) -> #N/A
A10: A | B10: '01121 | C10: PERTANIAN PADI HIBRIDA | D10: =VLOOKUP(Table13[[#This Row],[kbli5]],Table1[[#All],[kbli5]:[digital_hijau]],3,) -> #N/A | E10: =VLOOKUP(Table13[[#This Row],[kbli5]],kata_kunci!$B:$H,4,FALSE) -> #N/A | F10: =VLOOKUP(Table13[[#This Row],[kbli5]],Table1[[#All],[kbli5]:[digital_hijau]],5,) -> #N/A | G10: =VLOOKUP(Table13[[#This Row],[kbli5]],Table1[[#All],[kbli5]:[digital_hijau]],6,) -> #N/A | H10: =VLOOKUP(Table13[[#This Row],[kbli5]],kata_kunci!$B:$H,3,FALSE) -> #N/A | I10: =VLOOKUP(Table13[[#This Row],[kbli5]],kata_kunci!$B:$H,5,FALSE) -> #N/A | J10: =VLOOKUP(Table13[[#This Row],[kbli5]],kata_kunci!$B:$H,6,FALSE) -> #N/A | K10: =VLOOKUP(Table13[[#This Row],[kbli5]],kata_kunci!$B:$H,7,FALSE) -> #N/A
A11: A | B11: '01122 | C11: PERTANIAN PADI INBRIDA | D11: =VLOOKUP(Table13[[#This Row],[kbli5]],Table1[[#All],[kbli5]:[digital_hijau]],3,) -> #N/A | E11: =VLOOKUP(Table13[[#This Row],[kbli5]],kata_kunci!$B:$H,4,FALSE) -> #N/A | F11: =VLOOKUP(Table13[[#This Row],[kbli5]],Table1[[#All],[kbli5]:[digital_hijau]],5,) -> #N/A | G11: =VLOOKUP(Table13[[#This Row],[kbli5]],Table1[[#All],[kbli5]:[digital_hijau]],6,) -> #N/A | H11: =VLOOKUP(Table13[[#This Row],[kbli5]],kata_kunci!$B:$H,3,FALSE) -> #N/A | I11: =VLOOKUP(Table13[[#This Row],[kbli5]],kata_kunci!$B:$H,5,FALSE) -> #N/A | J11: =VLOOKUP(Table13[[#This Row],[kbli5]],kata_kunci!$B:$H,6,FALSE) -> #N/A | K11: =VLOOKUP(Table13[[#This Row],[kbli5]],kata_kunci!$B:$H,7,FALSE) -> #N/A
A12: A | B12: '01131 | C12: PERTANIAN SAYURAN DAUN | D12: =VLOOKUP(Table13[[#This Row],[kbli5]],Table1[[#All],[kbli5]:[digital_hijau]],3,) -> #N/A | E12: =VLOOKUP(Table13[[#This Row],[kbli5]],kata_kunci!$B:$H,4,FALSE) -> #N/A | F12: =VLOOKUP(Table13[[#This Row],[kbli5]],Table1[[#All],[kbli5]:[digital_hijau]],5,) -> #N/A | G12: =VLOOKUP(Table13[[#This Row],[kbli5]],Table1[[#All],[kbli5]:[digital_hijau]],6,) -> #N/A | H12: =VLOOKUP(Table13[[#This Row],[kbli5]],kata_kunci!$B:$H,3,FALSE) -> #N/A | I12: =VLOOKUP(Table13[[#This Row],[kbli5]],kata_kunci!$B:$H,5,FALSE) -> #N/A | J12: =VLOOKUP(Table13[[#This Row],[kbli5]],kata_kunci!$B:$H,6,FALSE) -> #N/A | K12: =VLOOKUP(Table13[[#This Row],[kbli5]],kata_kunci!$B:$H,7,FALSE) -> #N/A
A13: A | B13: '01132 | C13: PERTANIAN BUAH SEMUSIM | D13: =VLOOKUP(Table13[[#This Row],[kbli5]],Table1[[#All],[kbli5]:[digital_hijau]],3,) -> #N/A | E13: =VLOOKUP(Table13[[#This Row],[kbli5]],kata_kunci!$B:$H,4,FALSE) -> #N/A | F13: =VLOOKUP(Table13[[#This Row],[kbli5]],Table1[[#All],[kbli5]:[digital_hijau]],5,) -> #N/A | G13: =VLOOKUP(Table13[[#This Row],[kbli5]],Table1[[#All],[kbli5]:[digital_hijau]],6,) -> #N/A | H13: =VLOOKUP(Table13[[#This Row],[kbli5]],kata_kunci!$B:$H,3,FALSE) -> #N/A | I13: =VLOOKUP(Table13[[#This Row],[kbli5]],kata_kunci!$B:$H,5,FALSE) -> #N/A | J13: =VLOOKUP(Table13[[#This Row],[kbli5]],kata_kunci!$B:$H,6,FALSE) -> #N/A | K13: =VLOOKUP(Table13[[#This Row],[kbli5]],kata_kunci!$B:$H,7,FALSE) -> #N/A
... A126: B | B126: '05200 | C126: PERTAMBANGAN LIGNIT | D126: =VLOOKUP(Table13[[#This Row],[kbli5]],Table1[[#All],[kbli5]:[digital_hijau]],3,) -> #N/A | E126: =VLOOKUP(Table13[[#This Row],[kbli5]],kata_kunci!$B:$H,4,FALSE) -> #N/A | F126: =VLOOKUP(Table13[[#This Row],[kbli5]],Table1[[#All],[kbli5]:[digital_hijau]],5,) -> #N/A | G126: =VLOOKUP(Table13[[#This Row],[kbli5]],Table1[[#All],[kbli5]:[digital_hijau]],6,) -> #N/A | H126: =VLOOKUP(Table13[[#This Row],[kbli5]],kata_kunci!$B:$H,3,FALSE) -> #N/A | I126: =VLOOKUP(Table13[[#This Row],[kbli5]],kata_kunci!$B:$H,5,FALSE) -> #N/A | J126: =VLOOKUP(Table13[[#This Row],[kbli5]],kata_kunci!$B:$H,6,FALSE) -> #N/A | K126: =VLOOKUP(Table13[[#This Row],[kbli5]],kata_kunci!$B:$H,7,FALSE) -> #N/A
A127: B | B127: '06100 | C127: PERTAMBANGAN MINYAK BUMI | D127: =VLOOKUP(Table13[[#This Row],[kbli5]],Table1[[#All],[kbli5]:[digital_hijau]],3,) -> #N/A | E127: =VLOOKUP(Table13[[#This Row],[kbli5]],kata_kunci!$B:$H,4,FALSE) -> #N/A | F127: =VLOOKUP(Table13[[#This Row],[kbli5]],Table1[[#All],[kbli5]:[digital_hijau]],5,) -> #N/A | G127: Ekonomi Hijau; | H127: =VLOOKUP(Table13[[#This Row],[kbli5]],kata_kunci!$B:$H,3,FALSE) -> #N/A | I127: =VLOOKUP(Table13[[#This Row],[kbli5]],kata_kunci!$B:$H,5,FALSE) -> #N/A | J127: =VLOOKUP(Table13[[#This Row],[kbli5]],kata_kunci!$B:$H,6,FALSE) -> #N/A | K127: =VLOOKUP(Table13[[#This Row],[kbli5]],kata_kunci!$B:$H,7,FALSE) -> #N/A
A128: B | B128: '06201 | C128: PERTAMBANGAN GAS ALAM | D128: =VLOOKUP(Table13[[#This Row],[kbli5]],Table1[[#All],[kbli5]:[digital_hijau]],3,) -> #N/A | E128: =VLOOKUP(Table13[[#This Row],[kbli5]],kata_kunci!$B:$H,4,FALSE) -> #N/A | F128: =VLOOKUP(Table13[[#This Row],[kbli5]],Table1[[#All],[kbli5]:[digital_hijau]],5,) -> #N/A | G128: Ekonomi Hijau; | H128: =VLOOKUP(Table13[[#This Row],[kbli5]],kata_kunci!$B:$H,3,FALSE) -> #N/A | I128: =VLOOKUP(Table13[[#This Row],[kbli5]],kata_kunci!$B:$H,5,FALSE) -> #N/A | J128: =VLOOKUP(Table13[[#This Row],[kbli5]],kata_kunci!$B:$H,6,FALSE) -> #N/A | K128: =VLOOKUP(Table13[[#This Row],[kbli5]],kata_kunci!$B:$H,7,FALSE) -> #N/A
A129: B | B129: '06202 | C129: PENGUSAHAAN TENAGA PANAS BUMI | D129: =VLOOKUP(Table13[[#This Row],[kbli5]],Table1[[#All],[kbli5]:[digital_hijau]],3,) -> #N/A | E129: =VLOOKUP(Table13[[#This Row],[kbli5]],kata_kunci!$B:$H,4,FALSE) -> #N/A | F129: =VLOOKUP(Table13[[#This Row],[kbli5]],Table1[[#All],[kbli5]:[digital_hijau]],5,) -> #N/A | G129: Ekonomi Hijau; | H129: =VLOOKUP(Table13[[#This Row],[kbli5]],kata_kunci!$B:$H,3,FALSE) -> #N/A | I129: =VLOOKUP(Table13[[#This Row],[kbli5]],kata_kunci!$B:$H,5,FALSE) -> #N/A | J129: =VLOOKUP(Table13[[#This Row],[kbli5]],kata_kunci!$B:$H,6,FALSE) -> #N/A | K129: =VLOOKUP(Table13[[#This Row],[kbli5]],kata_kunci!$B:$H,7,FALSE) -> #N/A
A130: B | B130: '07101 | C130: PERTAMBANGAN PASIR BESI | D130: =VLOOKUP(Table13[[#This Row],[kbli5]],Table1[[#All],[kbli5]:[digital_hijau]],3,) -> #N/A | E130: =VLOOKUP(Table13[[#This Row],[kbli5]],kata_kunci!$B:$H,4,FALSE) -> #N/A | F130: =VLOOKUP(Table13[[#This Row],[kbli5]],Table1[[#All],[kbli5]:[digital_hijau]],5,) -> #N/A | G130: Ekonomi Hijau; | H130: =VLOOKUP(Table13[[#This Row],[kbli5]],kata_kunci!$B:$H,3,FALSE) -> #N/A | I130: =VLOOKUP(Table13[[#This Row],[kbli5]],kata_kunci!$B:$H,5,FALSE) -> #N/A | J130: =VLOOKUP(Table13[[#This Row],[kbli5]],kata_kunci!$B:$H,6,FALSE) -> #N/A | K130: =VLOOKUP(Table13[[#This Row],[kbli5]],kata_kunci!$B:$H,7,FALSE) -> #N/A
A131: B | B131: '07102 | C131: PERTAMBANGAN BIJIH BESI | D131: =VLOOKUP(Table13[[#This Row],[kbli5]],Table1[[#All],[kbli5]:[digital_hijau]],3,) -> #N/A | E131: =VLOOKUP(Table13[[#This Row],[kbli5]],kata_kunci!$B:$H,4,FALSE) -> #N/A | F131: =VLOOKUP(Table13[[#This Row],[kbli5]],Table1[[#All],[kbli5]:[digital_hijau]],5,) -> #N/A | G131: Ekonomi Hijau; | H131: =VLOOKUP(Table13[[#This Row],[kbli5]],kata_kunci!$B:$H,3,FALSE) -> #N/A | I131: =VLOOKUP(Table13[[#This Row],[kbli5]],kata_kunci!$B:$H,5,FALSE) -> #N/A | J131: =VLOOKUP(Table13[[#This Row],[kbli5]],kata_kunci!$B:$H,6,FALSE) -> #N/A | K131: =VLOOKUP(Table13[[#This Row],[kbli5]],kata_kunci!$B:$H,7,FALSE) -> #N/A
A132: B | B132: '07210 | C132: PERTAMBANGAN BIJIH URANIUM DAN TORIUM | D132: =VLOOKUP(Table13[[#This Row],[kbli5]],Table1[[#All],[kbli5]:[digital_hijau]],3,) -> #N/A | E132: =VLOOKUP(Table13[[#This Row],[kbli5]],kata_kunci!$B:$H,4,FALSE) -> #N/A | F132: =VLOOKUP(Table13[[#This Row],[kbli5]],Table1[[#All],[kbli5]:[digital_hijau]],5,) -> #N/A | G132: Ekonomi Hijau; | H132: =VLOOKUP(Table13[[#This Row],[kbli5]],kata_kunci!$B:$H,3,FALSE) -> #N/A | I132: =VLOOKUP(Table13[[#This Row],[kbli5]],kata_kunci!$B:$H,5,FALSE) -> #N/A | J132: =VLOOKUP(Table13[[#This Row],[kbli5]],kata_kunci!$B:$H,6,FALSE) -> #N/A | K132: =VLOOKUP(Table13[[#This Row],[kbli5]],kata_kunci!$B:$H,7,FALSE) -> #N/A
A133: B | B133: '07221 | C133: PERTAMBANGAN EMAS DAN PERAK | D133: =VLOOKUP(Table13[[#This Row],[kbli5]],Table1[[#All],[kbli5]:[digital_hijau]],3,) -> #N/A | E133: =VLOOKUP(Table13[[#This Row],[kbli5]],kata_kunci!$B:$H,4,FALSE) -> #N/A | F133: =VLOOKUP(Table13[[#This Row],[kbli5]],Table1[[#All],[kbli5]:[digital_hijau]],5,) -> #N/A | G133: Ekonomi Hijau; | H133: =VLOOKUP(Table13[[#This Row],[kbli5]],kata_kunci!$B:$H,3,FALSE) -> #N/A | I133: =VLOOKUP(Table13[[#This Row],[kbli5]],kata_kunci!$B:$H,5,FALSE) -> #N/A | J133: =VLOOKUP(Table13[[#This Row],[kbli5]],kata_kunci!$B:$H,6,FALSE) -> #N/A | K133: =VLOOKUP(Table13[[#This Row],[kbli5]],kata_kunci!$B:$H,7,FALSE) -> #N/A
A134: B | B134: '07229 | C134: PERTAMBANGAN BIJIH LOGAM MULIA LAINNYA | D134: =VLOOKUP(Table13[[#This Row],[kbli5]],Table1[[#All],[kbli5]:[digital_hijau]],3,) -> #N/A | E134: =VLOOKUP(Table13[[#This Row],[kbli5]],kata_kunci!$B:$H,4,FALSE) -> #N/A | F134: =VLOOKUP(Table13[[#This Row],[kbli5]],Table1[[#All],[kbli5]:[digital_hijau]],5,) -> #N/A | G134: Ekonomi Hijau; | H134: =VLOOKUP(Table13[[#This Row],[kbli5]],kata_kunci!$B:$H,3,FALSE) -> #N/A | I134: =VLOOKUP(Table13[[#This Row],[kbli5]],kata_kunci!$B:$H,5,FALSE) -> #N/A | J134: =VLOOKUP(Table13[[#This Row],[kbli5]],kata_kunci!$B:$H,6,FALSE) -> #N/A | K134: =VLOOKUP(Table13[[#This Row],[kbli5]],kata_kunci!$B:$H,7,FALSE) -> #N/A
A135: B | B135: '07291 | C135: PERTAMBANGAN BIJIH TIMAH | D135: =VLOOKUP(Table13[[#This Row],[kbli5]],Table1[[#All],[kbli5]:[digital_hijau]],3,) -> #N/A | E135: =VLOOKUP(Table13[[#This Row],[kbli5]],kata_kunci!$B:$H,4,FALSE) -> #N/A | F135: =VLOOKUP(Table13[[#This Row],[kbli5]],Table1[[#All],[kbli5]:[digital_hijau]],5,) -> #N/A | G135: Ekonomi Hijau; | H135: =VLOOKUP(Table13[[#This Row],[kbli5]],kata_kunci!$B:$H,3,FALSE) -> #N/A | I135: =VLOOKUP(Table13[[#This Row],[kbli5]],kata_kunci!$B:$H,5,FALSE) -> #N/A | J135: =VLOOKUP(Table13[[#This Row],[kbli5]],kata_kunci!$B:$H,6,FALSE) -> #N/A | K135: =VLOOKUP(Table13[[#This Row],[kbli5]],kata_kunci!$B:$H,7,FALSE) -> #N/A
A136: B | B136: '07292 | C136: PERTAMBANGAN BIJIH TIMAH HITAM | D136: =VLOOKUP(Table13[[#This Row],[kbli5]],Table1[[#All],[kbli5]:[digital_hijau]],3,) -> #N/A | E136: =VLOOKUP(Table13[[#This Row],[kbli5]],kata_kunci!$B:$H,4,FALSE) -> #N/A | F136: =VLOOKUP(Table13[[#This Row],[kbli5]],Table1[[#All],[kbli5]:[digital_hijau]],5,) -> #N/A | G136: Ekonomi Hijau; | H136: =VLOOKUP(Table13[[#This Row],[kbli5]],kata_kunci!$B:$H,3,FALSE) -> #N/A | I136: =VLOOKUP(Table13[[#This Row],[kbli5]],kata_kunci!$B:$H,5,FALSE) -> #N/A | J136: =VLOOKUP(Table13[[#This Row],[kbli5]],kata_kunci!$B:$H,6,FALSE) -> #N/A | K136: =VLOOKUP(Table13[[#This Row],[kbli5]],kata_kunci!$B:$H,7,FALSE) -> #N/A
A137: B | B137: '07293 | C137: PERTAMBANGAN BIJIH BAUKSIT | D137: =VLOOKUP(Table13[[#This Row],[kbli5]],Table1[[#All],[kbli5]:[digital_hijau]],3,) -> #N/A | E137: =VLOOKUP(Table13[[#This Row],[kbli5]],kata_kunci!$B:$H,4,FALSE) -> #N/A | F137: =VLOOKUP(Table13[[#This Row],[kbli5]],Table1[[#All],[kbli5]:[digital_hijau]],5,) -> #N/A | G137: Ekonomi Hijau; | H137: =VLOOKUP(Table13[[#This Row],[kbli5]],kata_kunci!$B:$H,3,FALSE) -> #N/A | I137: =VLOOKUP(Table13[[#This Row],[kbli5]],kata_kunci!$B:$H,5,FALSE) -> #N/A | J137: =VLOOKUP(Table13[[#This Row],[kbli5]],kata_kunci!$B:$H,6,FALSE) -> #N/A | K137: =VLOOKUP(Table13[[#This Row],[kbli5]],kata_kunci!$B:$H,7,FALSE) -> #N/A
A138: B | B138: '07294 | C138: PERTAMBANGAN BIJIH TEMBAGA | D138: =VLOOKUP(Table13[[#This Row],[kbli5]],Table1[[#All],[kbli5]:[digital_hijau]],3,) -> #N/A | E138: =VLOOKUP(Table13[[#This Row],[kbli5]],kata_kunci!$B:$H,4,FALSE) -> #N/A | F138: =VLOOKUP(Table13[[#This Row],[kbli5]],Table1[[#All],[kbli5]:[digital_hijau]],5,) -> #N/A | G138: Ekonomi Hijau; | H138: =VLOOKUP(Table13[[#This Row],[kbli5]],kata_kunci!$B:$H,3,FALSE) -> #N/A | I138: =VLOOKUP(Table13[[#This Row],[kbli5]],kata_kunci!$B:$H,5,FALSE) -> #N/A | J138: =VLOOKUP(Table13[[#This Row],[kbli5]],kata_kunci!$B:$H,6,FALSE) -> #N/A | K138: =VLOOKUP(Table13[[#This Row],[kbli5]],kata_kunci!$B:$H,7,FALSE) -> #N/A
A139: B | B139: '07295 | C139: PERTAMBANGAN BIJIH NIKEL | D139: =VLOOKUP(Table13[[#This Row],[kbli5]],Table1[[#All],[kbli5]:[digital_hijau]],3,) -> #N/A | E139: =VLOOKUP(Table13[[#This Row],[kbli5]],kata_kunci!$B:$H,4,FALSE) -> #N/A | F139: =VLOOKUP(Table13[[#This Row],[kbli5]],Table1[[#All],[kbli5]:[digital_hijau]],5,) -> #N/A | G139: Ekonomi Hijau; | H139: =VLOOKUP(Table13[[#This Row],[kbli5]],kata_kunci!$B:$H,3,FALSE) -> #N/A | I139: =VLOOKUP(Table13[[#This Row],[kbli5]],kata_kunci!$B:$H,5,FALSE) -> #N/A | J139: =VLOOKUP(Table13[[#This Row],[kbli5]],kata_kunci!$B:$H,6,FALSE) -> #N/A | K139: =VLOOKUP(Table13[[#This Row],[kbli5]],kata_kunci!$B:$H,7,FALSE) -> #N/A
A140: B | B140: '07296 | C140: PERTAMBANGAN BIJIH MANGAN | D140: =VLOOKUP(Table13[[#This Row],[kbli5]],Table1[[#All],[kbli5]:[digital_hijau]],3,) -> #N/A | E140: =VLOOKUP(Table13[[#This Row],[kbli5]],kata_kunci!$B:$H,4,FALSE) -> #N/A | F140: =VLOOKUP(Table13[[#This Row],[kbli5]],Table1[[#All],[kbli5]:[digital_hijau]],5,) -> #N/A | G140: =VLOOKUP(Table13[[#This Row],[kbli5]],Table1[[#All],[kbli5]:[digital_hijau]],6,) -> #N/A | H140: =VLOOKUP(Table13[[#This Row],[kbli5]],kata_kunci!$B:$H,3,FALSE) -> #N/A | I140: =VLOOKUP(Table13[[#This Row],[kbli5]],kata_kunci!$B:$H,5,FALSE) -> #N/A | J140: =VLOOKUP(Table13[[#This Row],[kbli5]],kata_kunci!$B:$H,6,FALSE) -> #N/A | K140: =VLOOKUP(Table13[[#This Row],[kbli5]],kata_kunci!$B:$H,7,FALSE) -> #N/A
A141: B | B141: '07299 | C141: PERTAMBANGAN BAHAN GALIAN LAINNYA YANG TIDAK MENGANDUNG | D141: =VLOOKUP(Table13[[#This Row],[kbli5]],Table1[[#All],[kbli5]:[digital_hijau]],3,) -> #N/A | E141: =VLOOKUP(Table13[[#This Row],[kbli5]],kata_kunci!$B:$H,4,FALSE) -> #N/A | F141: =VLOOKUP(Table13[[#This Row],[kbli5]],Table1[[#All],[kbli5]:[digital_hijau]],5,) -> #N/A | G141: =VLOOKUP(Table13[[#This Row],[kbli5]],Table1[[#All],[kbli5]:[digital_hijau]],6,) -> #N/A | H141: =VLOOKUP(Table13[[#This Row],[kbli5]],kata_kunci!$B:$H,3,FALSE) -> #N/A | I141: =VLOOKUP(Table13[[#This Row],[kbli5]],kata_kunci!$B:$H,5,FALSE) -> #N/A | J141: =VLOOKUP(Table13[[#This Row],[kbli5]],kata_kunci!$B:$H,6,FALSE) -> #N/A | K141: =VLOOKUP(Table13[[#This Row],[kbli5]],kata_kunci!$B:$H,7,FALSE) -> #N/A
A142: B | B142: '08101 | C142: PENGGALIAN BATU HIAS DAN BATU BANGUNAN | D142: =VLOOKUP(Table13[[#This Row],[kbli5]],Table1[[#All],[kbli5]:[digital_hijau]],3,) -> #N/A | E142: =VLOOKUP(Table13[[#This Row],[kbli5]],kata_kunci!$B:$H,4,FALSE) -> #N/A | F142: =VLOOKUP(Table13[[#This Row],[kbli5]],Table1[[#All],[kbli5]:[digital_hijau]],5,) -> #N/A | G142: =VLOOKUP(Table13[[#This Row],[kbli5]],Table1[[#All],[kbli5]:[digital_hijau]],6,) -> #N/A | H142: =VLOOKUP(Table13[[#This Row],[kbli5]],kata_kunci!$B:$H,3,FALSE) -> #N/A | I142: =VLOOKUP(Table13[[#This Row],[kbli5]],kata_kunci!$B:$H,5,FALSE) -> #N/A | J142: =VLOOKUP(Table13[[#This Row],[kbli5]],kata_kunci!$B:$H,6,FALSE) -> #N/A | K142: =VLOOKUP(Table13[[#This Row],[kbli5]],kata_kunci!$B:$H,7,FALSE) -> #N/A
A143: B | B143: '08102 | C143: PENGGALIAN BATU KAPUR/GAMPING | D143: =VLOOKUP(Table13[[#This Row],[kbli5]],Table1[[#All],[kbli5]:[digital_hijau]],3,) -> #N/A | E143: =VLOOKUP(Table13[[#This Row],[kbli5]],kata_kunci!$B:$H,4,FALSE) -> #N/A | F143: =VLOOKUP(Table13[[#This Row],[kbli5]],Table1[[#All],[kbli5]:[digital_hijau]],5,) -> #N/A | G143: =VLOOKUP(Table13[[#This Row],[kbli5]],Table1[[#All],[kbli5]:[digital_hijau]],6,) -> #N/A | H143: =VLOOKUP(Table13[[#This Row],[kbli5]],kata_kunci!$B:$H,3,FALSE) -> #N/A | I143: =VLOOKUP(Table13[[#This Row],[kbli5]],kata_kunci!$B:$H,5,FALSE) -> #N/A | J143: =VLOOKUP(Table13[[#This Row],[kbli5]],kata_kunci!$B:$H,6,FALSE) -> #N/A | K143: =VLOOKUP(Table13[[#This Row],[kbli5]],kata_kunci!$B:$H,7,FALSE) -> #N/A
A144: B | B144: '08103 | C144: PENGGALIAN KERIKIL/SIRTU | D144: =VLOOKUP(Table13[[#This Row],[kbli5]],Table1[[#All],[kbli5]:[digital_hijau]],3,) -> #N/A | E144: =VLOOKUP(Table13[[#This Row],[kbli5]],kata_kunci!$B:$H,4,FALSE) -> #N/A | F144: =VLOOKUP(Table13[[#This Row],[kbli5]],Table1[[#All],[kbli5]:[digital_hijau]],5,) -> #N/A | G144: =VLOOKUP(Table13[[#This Row],[kbli5]],Table1[[#All],[kbli5]:[digital_hijau]],6,) -> #N/A | H144: =VLOOKUP(Table13[[#This Row],[kbli5]],kata_kunci!$B:$H,3,FALSE) -> #N/A | I144: =VLOOKUP(Table13[[#This Row],[kbli5]],kata_kunci!$B:$H,5,FALSE) -> #N/A | J144: =VLOOKUP(Table13[[#This Row],[kbli5]],kata_kunci!$B:$H,6,FALSE) -> #N/A | K144: =VLOOKUP(Table13[[#This Row],[kbli5]],kata_kunci!$B:$H,7,FALSE) -> #N/A
A145: B | B145: '08104 | C145: PENGGALIAN PASIR | D145: =VLOOKUP(Table13[[#This Row],[kbli5]],Table1[[#All],[kbli5]:[digital_hijau]],3,) -> #N/A | E145: =VLOOKUP(Table13[[#This Row],[kbli5]],kata_kunci!$B:$H,4,FALSE) -> #N/A | F145: =VLOOKUP(Table13[[#This Row],[kbli5]],Table1[[#All],[kbli5]:[digital_hijau]],5,) -> #N/A | G145: =VLOOKUP(Table13[[#This Row],[kbli5]],Table1[[#All],[kbli5]:[digital_hijau]],6,) -> #N/A | H145: =VLOOKUP(Table13[[#This Row],[kbli5]],kata_kunci!$B:$H,3,FALSE) -> #N/A | I145: =VLOOKUP(Table13[[#This Row],[kbli5]],kata_kunci!$B:$H,5,FALSE) -> #N/A | J145: =VLOOKUP(Table13[[#This Row],[kbli5]],kata_kunci!$B:$H,6,FALSE) -> #N/A | K145: =VLOOKUP(Table13[[#This Row],[kbli5]],kata_kunci!$B:$H,7,FALSE) -> #N/A
A146: B | B146: '08105 | C146: PENGGALIAN TANAH DAN TANAH LIAT | D146: =VLOOKUP(Table13[[#This Row],[kbli5]],Table1[[#All],[kbli5]:[digital_hijau]],3,) -> #N/A | E146: =VLOOKUP(Table13[[#This Row],[kbli5]],kata_kunci!$B:$H,4,FALSE) -> #N/A | F146: =VLOOKUP(Table13[[#This Row],[kbli5]],Table1[[#All],[kbli5]:[digital_hijau]],5,) -> #N/A | G146: =VLOOKUP(Table13[[#This Row],[kbli5]],Table1[[#All],[kbli5]:[digital_hijau]],6,) -> #N/A | H146: =VLOOKUP(Table13[[#This Row],[kbli5]],kata_kunci!$B:$H,3,FALSE) -> #N/A | I146: =VLOOKUP(Table13[[#This Row],[kbli5]],kata_kunci!$B:$H,5,FALSE) -> #N/A | J146: =VLOOKUP(Table13[[#This Row],[kbli5]],kata_kunci!$B:$H,6,FALSE) -> #N/A | K146: =VLOOKUP(Table13[[#This Row],[kbli5]],kata_kunci!$B:$H,7,FALSE) -> #N/A
A147: B | B147: '08106 | C147: PENGGALIAN GIPS | D147: =VLOOKUP(Table13[[#This Row],[kbli5]],Table1[[#All],[kbli5]:[digital_hijau]],3,) -> #N/A | E147: =VLOOKUP(Table13[[#This Row],[kbli5]],kata_kunci!$B:$H,4,FALSE) -> #N/A | F147: =VLOOKUP(Table13[[#This Row],[kbli5]],Table1[[#All],[kbli5]:[digital_hijau]],5,) -> #N/A | G147: =VLOOKUP(Table13[[#This Row],[kbli5]],Table1[[#All],[kbli5]:[digital_hijau]],6,) -> #N/A | H147: =VLOOKUP(Table13[[#This Row],[kbli5]],kata_kunci!$B:$H,3,FALSE) -> #N/A | I147: =VLOOKUP(Table13[[#This Row],[kbli5]],kata_kunci!$B:$H,5,FALSE) -> #N/A | J147: =VLOOKUP(Table13[[#This Row],[kbli5]],kata_kunci!$B:$H,6,FALSE) -> #N/A | K147: =VLOOKUP(Table13[[#This Row],[kbli5]],kata_kunci!$B:$H,7,FALSE) -> #N/A
A148: B | B148: '08107 | C148: PENGGALIAN TRAS | D148: =VLOOKUP(Table13[[#This Row],[kbli5]],Table1[[#All],[kbli5]:[digital_hijau]],3,) -> #N/A | E148: =VLOOKUP(Table13[[#This Row],[kbli5]],kata_kunci!$B:$H,4,FALSE) -> #N/A | F148: =VLOOKUP(Table13[[#This Row],[kbli5]],Table1[[#All],[kbli5]:[digital_hijau]],5,) -> #N/A | G148: =VLOOKUP(Table13[[#This Row],[kbli5]],Table1[[#All],[kbli5]:[digital_hijau]],6,) -> #N/A | H148: =VLOOKUP(Table13[[#This Row],[kbli5]],kata_kunci!$B:$H,3,FALSE) -> #N/A | I148: =VLOOKUP(Table13[[#This Row],[kbli5]],kata_kunci!$B:$H,5,FALSE) -> #N/A | J148: =VLOOKUP(Table13[[#This Row],[kbli5]],kata_kunci!$B:$H,6,FALSE) -> #N/A | K148: =VLOOKUP(Table13[[#This Row],[kbli5]],kata_kunci!$B:$H,7,FALSE) -> #N/A
A149: B | B149: '08108 | C149: PENGGALIAN BATU APUNG | D149: =VLOOKUP(Table13[[#This Row],[kbli5]],Table1[[#All],[kbli5]:[digital_hijau]],3,) -> #N/A | E149: =VLOOKUP(Table13[[#This Row],[kbli5]],kata_kunci!$B:$H,4,FALSE) -> #N/A | F149: =VLOOKUP(Table13[[#This Row],[kbli5]],Table1[[#All],[kbli5]:[digital_hijau]],5,) -> #N/A | G149: =VLOOKUP(Table13[[#This Row],[kbli5]],Table1[[#All],[kbli5]:[digital_hijau]],6,) -> #N/A | H149: =VLOOKUP(Table13[[#This Row],[kbli5]],kata_kunci!$B:$H,3,FALSE) -> #N/A | I149: =VLOOKUP(Table13[[#This Row],[kbli5]],kata_kunci!$B:$H,5,FALSE) -> #N/A | J149: =VLOOKUP(Table13[[#This Row],[kbli5]],kata_kunci!$B:$H,6,FALSE) -> #N/A | K149: =VLOOKUP(Table13[[#This Row],[kbli5]],kata_kunci!$B:$H,7,FALSE) -> #N/A
A150: B | B150: '08109 | C150: PENGGALIAN BATU, PASIR, DAN TANAH LIAT LAINNYA | D150: =VLOOKUP(Table13[[#This Row],[kbli5]],Table1[[#All],[kbli5]:[digital_hijau]],3,) -> #N/A | E150: =VLOOKUP(Table13[[#This Row],[kbli5]],kata_kunci!$B:$H,4,FALSE) -> #N/A | F150: =VLOOKUP(Table13[[#This Row],[kbli5]],Table1[[#All],[kbli5]:[digital_hijau]],5,) -> #N/A | G150: =VLOOKUP(Table13[[#This Row],[kbli5]],Table1[[#All],[kbli5]:[digital_hijau]],6,) -> #N/A | H150: =VLOOKUP(Table13[[#This Row],[kbli5]],kata_kunci!$B:$H,3,FALSE) -> #N/A | I150: =VLOOKUP(Table13[[#This Row],[kbli5]],kata_kunci!$B:$H,5,FALSE) -> #N/A | J150: =VLOOKUP(Table13[[#This Row],[kbli5]],kata_kunci!$B:$H,6,FALSE) -> #N/A | K150: =VLOOKUP(Table13[[#This Row],[kbli5]],kata_kunci!$B:$H,7,FALSE) -> #N/A
A151: B | B151: '08911 | C151: PERTAMBANGAN BELERANG | D151: =VLOOKUP(Table13[[#This Row],[kbli5]],Table1[[#All],[kbli5]:[digital_hijau]],3,) -> #N/A | E151: =VLOOKUP(Table13[[#This Row],[kbli5]],kata_kunci!$B:$H,4,FALSE) -> #N/A | F151: =VLOOKUP(Table13[[#This Row],[kbli5]],Table1[[#All],[kbli5]:[digital_hijau]],5,) -> #N/A | G151: =VLOOKUP(Table13[[#This Row],[kbli5]],Table1[[#All],[kbli5]:[digital_hijau]],6,) -> #N/A | H151: =VLOOKUP(Table13[[#This Row],[kbli5]],kata_kunci!$B:$H,3,FALSE) -> #N/A | I151: =VLOOKUP(Table13[[#This Row],[kbli5]],kata_kunci!$B:$H,5,FALSE) -> #N/A | J151: =VLOOKUP(Table13[[#This Row],[kbli5]],kata_kunci!$B:$H,6,FALSE) -> #N/A | K151: =VLOOKUP(Table13[[#This Row],[kbli5]],kata_kunci!$B:$H,7,FALSE) -> #N/A
... A167: B | B167: '09900 | C167: AKTIVITAS PENUNJANG PERTAMBANGAN DAN PENGGALIAN LAINNYA | D167: =VLOOKUP(Table13[[#This Row],[kbli5]],Table1[[#All],[kbli5]:[digital_hijau]],3,) -> #N/A | E167: =VLOOKUP(Table13[[#This Row],[kbli5]],kata_kunci!$B:$H,4,FALSE) -> #N/A | F167: =VLOOKUP(Table13[[#This Row],[kbli5]],Table1[[#All],[kbli5]:[digital_hijau]],5,) -> #N/A | G167: =VLOOKUP(Table13[[#This Row],[kbli5]],Table1[[#All],[kbli5]:[digital_hijau]],6,) -> #N/A | H167: =VLOOKUP(Table13[[#This Row],[kbli5]],kata_kunci!$B:$H,3,FALSE) -> #N/A | I167: =VLOOKUP(Table13[[#This Row],[kbli5]],kata_kunci!$B:$H,5,FALSE) -> #N/A | J167: =VLOOKUP(Table13[[#This Row],[kbli5]],kata_kunci!$B:$H,6,FALSE) -> #N/A | K167: =VLOOKUP(Table13[[#This Row],[kbli5]],kata_kunci!$B:$H,7,FALSE) -> #N/A
...

Sheet rapikan
A1: kbli5 | B1: judul | C1: contoh_usaha | D1: kata_kunci | E1: kategori | F1: digital_hijau | G1: versi 1 | H1: cek | I1: kbli1
A2: 55101 | B2: =VLOOKUP(Table1[[#This Row],[kbli5]],master!$A$2:$B$1560,2,FALSE) -> AKTIVITAS HOTEL BINTANG LIMA | C2: Hotel Btg 5; Hotel internasional berbintang lima (misalnya jaringan hotel global); Resort mewah dengan standar bintang lima; Labersa hotel; Araduta hotel; | E2: Esensial | F2: Industri Digital; Ekonomi Hijau; | G2: =VLOOKUP(Table1[[#This Row],[kbli5]],data_versi1!$B$2:$D$101,3, FALSE) -> Hotel Btg 5; Hotel internasional berbintang lima (misalnya jaringan hotel global); Resort mewah dengan standar bintang lima; Labersa hotel; Araduta hotel; | H2: =IF(Table1[[#This Row],[contoh_usaha]]=Table1[[#This Row],[versi 1]],TRUE,FALSE) -> TRUE | I2: I
A3: 55102 | B3: =VLOOKUP(Table1[[#This Row],[kbli5]],master!$A$2:$B$1560,2,FALSE) -> AKTIVITAS HOTEL BINTANG EMPAT | C3: Hotel Btg 4; Premiere; Fox; Zuri PKU & Dumai; Asnof; | E3: Esensial | G3: =VLOOKUP(Table1[[#This Row],[kbli5]],data_versi1!$B$2:$D$101,3, FALSE) -> Hotel Btg 4; Premiere; Fox; Zuri PKU & Dumai; Asnof; | H3: =IF(Table1[[#This Row],[contoh_usaha]]=Table1[[#This Row],[versi 1]],TRUE,FALSE) -> TRUE | I3: I
A4: 55103 | B4: =VLOOKUP(Table1[[#This Row],[kbli5]],master!$A$2:$B$1560,2,FALSE) -> AKTIVITAS HOTEL BINTANG TIGA | C4: Hotel Btg 3; Swiss Bellin SKA; Furaya; Dafam; | E4: Esensial | G4: =VLOOKUP(Table1[[#This Row],[kbli5]],data_versi1!$B$2:$D$101,3, FALSE) -> Hotel Btg 3; Swiss Bellin SKA; Furaya; Dafam; | H4: =IF(Table1[[#This Row],[contoh_usaha]]=Table1[[#This Row],[versi 1]],TRUE,FALSE) -> TRUE | I4: I
A5: 55104 | B5: =VLOOKUP(Table1[[#This Row],[kbli5]],master!$A$2:$B$1560,2,FALSE) -> AKTIVITAS HOTEL BINTANG DUA | C5: Hotel Btg 2; | E5: Esensial | G5: =VLOOKUP(Table1[[#This Row],[kbli5]],data_versi1!$B$2:$D$101,3, FALSE) -> Hotel Btg 2; | H5: =IF(Table1[[#This Row],[contoh_usaha]]=Table1[[#This Row],[versi 1]],TRUE,FALSE) -> TRUE | I5: I
A6: 55105 | B6: =VLOOKUP(Table1[[#This Row],[kbli5]],master!$A$2:$B$1560,2,FALSE) -> AKTIVITAS HOTEL BINTANG SATU | C6: Hotel Btg 1; Hotel melati berbintang; Budget hotel; Hotel transit sederhana; Hotel wisata kecil; holiday hotel; sabrina 45 hotel; | E6: Esensial | G6: =VLOOKUP(Table1[[#This Row],[kbli5]],data_versi1!$B$2:$D$101,3, FALSE) -> Hotel Btg 1; Hotel melati berbintang; Budget hotel; Hotel transit sederhana; Hotel wisata kecil; holiday hotel; sabrina 45 hotel; | H6: =IF(Table1[[#This Row],[contoh_usaha]]=Table1[[#This Row],[versi 1]],TRUE,FALSE) -> TRUE | I6: I
A7: 55106 | B7: =VLOOKUP(Table1[[#This Row],[kbli5]],master!$A$2:$B$1560,2,FALSE) -> AKTIVITAS HOTEL NONBINTANG | C7: Hotel Non Bintang; Losmen; Wisma penginapan; Hotel melati; Guest house sederhana; Penginapan harian; | E7: Esensial | G7: =VLOOKUP(Table1[[#This Row],[kbli5]],data_versi1!$B$2:$D$101,3, FALSE) -> Hotel Non Bintang; Losmen; Wisma penginapan; Hotel melati; Guest house sederhana; Penginapan harian; | H7: =IF(Table1[[#This Row],[contoh_usaha]]=Table1[[#This Row],[versi 1]],TRUE,FALSE) -> TRUE | I7: I
A8: 55201 | B8: =VLOOKUP(Table1[[#This Row],[kbli5]],master!$A$2:$B$1560,2,FALSE) -> AKTIVITAS RUMAH TINGGAL SEWA (HOMESTAY) | C8: Homestay; Cottage wisata pantai; Bungalow resort; Cabin wisata alam; Eco lodge; Penginapan wisata keluarga; | E8: Esensial | G8: =VLOOKUP(Table1[[#This Row],[kbli5]],data_versi1!$B$2:$D$101,3, FALSE) -> Homestay; Cottage wisata pantai; Bungalow resort; Cabin wisata alam; Eco lodge; Penginapan wisata keluarga; | H8: =IF(Table1[[#This Row],[contoh_usaha]]=Table1[[#This Row],[versi 1]],TRUE,FALSE) -> TRUE | I8: I
A9: 55202 | B9: =VLOOKUP(Table1[[#This Row],[kbli5]],master!$A$2:$B$1560,2,FALSE) -> AKTIVITAS HOSTEL REMAJA (YOUTH HOSTEL) | C9: Hostel Remaja; Bumi perkemahan; Camping ground; Kemping; Karavan; Campervan; Area camping; Wisata alam; | E9: Potensial | G9: =VLOOKUP(Table1[[#This Row],[kbli5]],data_versi1!$B$2:$D$101,3, FALSE) -> #N/A | H9: =IF(Table1[[#This Row],[contoh_usaha]]=Table1[[#This Row],[versi 1]],TRUE,FALSE) -> #N/A | I9: I
A10: 55203 | B10: =VLOOKUP(Table1[[#This Row],[kbli5]],master!$A$2:$B$1560,2,FALSE) -> AKTIVITAS VILA | C10: Aktivitas Vila; Vila wisata keluarga; Vila pegunungan; Vila pantai; Private villa; Resort villa; | E10: Potensial | G10: =VLOOKUP(Table1[[#This Row],[kbli5]],data_versi1!$B$2:$D$101,3, FALSE) -> #N/A | H10: =IF(Table1[[#This Row],[contoh_usaha]]=Table1[[#This Row],[versi 1]],TRUE,FALSE) -> #N/A | I10: I
A11: 55204 | B11: =VLOOKUP(Table1[[#This Row],[kbli5]],master!$A$2:$B$1560,2,FALSE) -> AKTIVITAS APARTEMEN HOTEL | C11: Apartemen hotel; Kampar Lake Villa; Riau Holiday House; Pekanbaru Guest House; Siak Heritage Cottage; Bengkalis Beach Bungalow; | E11: Umum Ditemukan | G11: =VLOOKUP(Table1[[#This Row],[kbli5]],data_versi1!$B$2:$D$101,3, FALSE) -> Apartemen hotel; Kampar Lake Villa; Riau Holiday House; Pekanbaru Guest House; Siak Heritage Cottage; Bengkalis Beach Bungalow; | H11: =IF(Table1[[#This Row],[contoh_usaha]]=Table1[[#This Row],[versi 1]],TRUE,FALSE) -> TRUE | I11: I
A12: 55209 | B12: =VLOOKUP(Table1[[#This Row],[kbli5]],master!$A$2:$B$1560,2,FALSE) -> AKTIVITAS PENYEDIAAN AKOMODASI JANGKA PENDEK LAINNYA | C12: Akomodasi jangka pendek lainnya; Bono Riverside Lodge; Siak Heritage Stay; Kampar Tourist House; Riau Visitor Lodge; Wisma Wisata Melayu; | E12: Umum Ditemukan | G12: =VLOOKUP(Table1[[#This Row],[kbli5]],data_versi1!$B$2:$D$101,3, FALSE) -> Akomodasi jangka pendek lainnya; Bono Riverside Lodge; Siak Heritage Stay; Kampar Tourist House; Riau Visitor Lodge; Wisma Wisata Melayu; | H12: =IF(Table1[[#This Row],[contoh_usaha]]=Table1[[#This Row],[versi 1]],TRUE,FALSE) -> TRUE | I12: I
A13: 55300 | B13: =VLOOKUP(Table1[[#This Row],[kbli5]],master!$A$2:$B$1560,2,FALSE) -> AKTIVITAS PENYEDIAAN BUMI PERKEMAHAN, PERSINGGAHAN KARAVAN, | C13: Bumi Perkemahan; Camping Ground Kampar; Campervan Park; Eco Camp; | E13: Umum Ditemukan | G13: =VLOOKUP(Table1[[#This Row],[kbli5]],data_versi1!$B$2:$D$101,3, FALSE) -> Bumi Perkemahan; Camping Ground Kampar; Campervan Park; Eco Camp; | H13: =IF(Table1[[#This Row],[contoh_usaha]]=Table1[[#This Row],[versi 1]],TRUE,FALSE) -> TRUE | I13: I
A14: 55901 | B14: =VLOOKUP(Table1[[#This Row],[kbli5]],master!$A$2:$B$1560,2,FALSE) -> AKTIVITAS JASA MANAJEMEN AKOMODASI | C14: Jasa manajemen akomodasi; Asrama Mahasiswa Riau; Mess Karyawan Sawit Jaya; Dormitory Pekanbaru; Asrama Atlet Riau; Graha Asrama Nusantara; | E14: Umum Ditemukan | G14: =VLOOKUP(Table1[[#This Row],[kbli5]],data_versi1!$B$2:$D$101,3, FALSE) -> Jasa manajemen akomodasi; Asrama Mahasiswa Riau; Mess Karyawan Sawit Jaya; Dormitory Pekanbaru; Asrama Atlet Riau; Graha Asrama Nusantara; | H14: =IF(Table1[[#This Row],[contoh_usaha]]=Table1[[#This Row],[versi 1]],TRUE,FALSE) -> TRUE | I14: I
... A27: 61101 | B27: =VLOOKUP(Table1[[#This Row],[kbli5]],master!$A$2:$B$1560,2,FALSE) -> AKTIVITAS TELEKOMUNIKASI DENGAN KABEL | C27: Telekomunikasi kabel; Indihome; | E27: Umum Ditemukan | G27: =VLOOKUP(Table1[[#This Row],[kbli5]],data_versi1!$B$2:$D$101,3, FALSE) -> Telekomunikasi kabel; Indihome; | H27: =IF(Table1[[#This Row],[contoh_usaha]]=Table1[[#This Row],[versi 1]],TRUE,FALSE) -> TRUE | I27: K
A28: 61102 | B28: =VLOOKUP(Table1[[#This Row],[kbli5]],master!$A$2:$B$1560,2,FALSE) -> AKTIVITAS TELEKOMUNIKASI DENGAN NIRKABEL | C28: Telekomunikasi kabel; Telkomsel; | E28: Umum Ditemukan | F28: Industri Digital; | G28: =VLOOKUP(Table1[[#This Row],[kbli5]],data_versi1!$B$2:$D$101,3, FALSE) -> Telekomunikasi kabel; Telkomsel; | H28: =IF(Table1[[#This Row],[contoh_usaha]]=Table1[[#This Row],[versi 1]],TRUE,FALSE) -> TRUE | I28: K
A29: 61104 | B29: =VLOOKUP(Table1[[#This Row],[kbli5]],master!$A$2:$B$1560,2,FALSE) -> AKTIVITAS JASA AKSES INTERNET (INTERNET SERVICE PROVIDER) | C29: ISP; Indihome; perusahaan penyedia wifi untuk internet di rumah; my republik; cipta informatika cemerlang; solnet; | E29: Umum Ditemukan | F29: Industri Digital; | G29: =VLOOKUP(Table1[[#This Row],[kbli5]],data_versi1!$B$2:$D$101,3, FALSE) -> ISP; Indihome; perusahaan penyedia wifi untuk internet di rumah; my republik; cipta informatika cemerlang; solnet; | H29: =IF(Table1[[#This Row],[contoh_usaha]]=Table1[[#This Row],[versi 1]],TRUE,FALSE) -> TRUE | I29: K
A30: 61106 | B30: =VLOOKUP(Table1[[#This Row],[kbli5]],master!$A$2:$B$1560,2,FALSE) -> AKTIVITIAS JASA TELEVISI PROTOKOL INTERNET (IPTV) | C30: Tv protokol internet (IPTV); Indihome TV; MNC Play; FirstMedia; UseeTV | E30: Umum Ditemukan | F30: Industri Digital; | G30: =VLOOKUP(Table1[[#This Row],[kbli5]],data_versi1!$B$2:$D$101,3, FALSE) -> Tv protokol internet (IPTV); Indihome TV; MNC Play; FirstMedia; UseeTV | H30: =IF(Table1[[#This Row],[contoh_usaha]]=Table1[[#This Row],[versi 1]],TRUE,FALSE) -> TRUE | I30: K
A31: 61209 | B31: =VLOOKUP(Table1[[#This Row],[kbli5]],master!$A$2:$B$1560,2,FALSE) -> AKTIVITAS PENJUALAN KEMBALI DAN JASA INTERMEDIASI UNTUK TELEKOMUNIKASI LAINNYA | C31: Jasa Intemediasi Telekomunikasi; wartel, warnet; jasa pihak ketiga yang memasang wifi/ kabel & tiang internet; pemasangan tv kabel; JUAL PULSA; KONTER PULSA; jual kartu perdana; | E31: Umum Ditemukan | F31: Industri Digital; | G31: =VLOOKUP(Table1[[#This Row],[kbli5]],data_versi1!$B$2:$D$101,3, FALSE) -> Jasa Intemediasi Telekomunikasi; wartel, warnet; jasa pihak ketiga yang memasang wifi/ kabel & tiang internet; pemasangan tv kabel; JUAL PULSA; KONTER PULSA; jual kartu perdana; | H31: =IF(Table1[[#This Row],[contoh_usaha]]=Table1[[#This Row],[versi 1]],TRUE,FALSE) -> TRUE | I31: K
A32: 62199 | B32: =VLOOKUP(Table1[[#This Row],[kbli5]],master!$A$2:$B$1560,2,FALSE) -> AKTIVITAS PEMROGRAMAN KOMPUTER LAINNYA YTDL | C32: Aktivitas pemrograman; programmer freelance; perusahaan digital pembuatan aplikasi/website (ada kegiatan pemrograman di dalamnya); | E32: Umum Ditemukan | F32: Industri Digital; | G32: =VLOOKUP(Table1[[#This Row],[kbli5]],data_versi1!$B$2:$D$101,3, FALSE) -> Aktivitas pemrograman; programmer freelance; perusahaan digital pembuatan aplikasi/website (ada kegiatan pemrograman di dalamnya); | H32: =IF(Table1[[#This Row],[contoh_usaha]]=Table1[[#This Row],[versi 1]],TRUE,FALSE) -> TRUE | I32: K
A33: 62900 | B33: =VLOOKUP(Table1[[#This Row],[kbli5]],master!$A$2:$B$1560,2,FALSE) -> AKTIVITAS JASA TEKNOLOGI INFORMASI DAN KOMPUTER LAINNYA | C33: Jasa TI dan komputer lainnya; jasa perbaikan komputer; jasa servis komputer;jasa instalasi perangkat komputer; jasa servis perangkat TI lainnya; retyan computer; megakom; | E33: Umum Ditemukan | F33: Industri Digital; | G33: =VLOOKUP(Table1[[#This Row],[kbli5]],data_versi1!$B$2:$D$101,3, FALSE) -> Jasa TI dan komputer lainnya; jasa perbaikan komputer; jasa servis komputer;jasa instalasi perangkat komputer; jasa servis perangkat TI lainnya; retyan computer; megakom; | H33: =IF(Table1[[#This Row],[contoh_usaha]]=Table1[[#This Row],[versi 1]],TRUE,FALSE) -> TRUE | I33: K
A34: 35111 | B34: =VLOOKUP(Table1[[#This Row],[kbli5]],master!$A$2:$B$1560,2,FALSE) -> PEMBANGKITAN TENAGA LISTRIK DARI SUMBER ENERGI TIDAK | C34: PLTU Tenayan Pekanbaru; PLTGU Riau Pekanbaru; PLTMG Balai Pungut Bengkalis; PLTMG Teluk Lembu; Turbin Gas PHR; PLTU Batu Bara Industri; | E34: Esensial | G34: =VLOOKUP(Table1[[#This Row],[kbli5]],data_versi1!$B$2:$D$101,3, FALSE) -> #N/A | H34: =IF(Table1[[#This Row],[contoh_usaha]]=Table1[[#This Row],[versi 1]],TRUE,FALSE) -> #N/A | I34: D
A35: 35120 | B35: =VLOOKUP(Table1[[#This Row],[kbli5]],master!$A$2:$B$1560,2,FALSE) -> PEMBANGKITAN TENAGA LISTRIK DARI SUMBER ENERGI TERBARUKAN | C35: PLTA Koto Panjang Kampar; Pembangkit Biomassa PT RAPP & PT IKPP; PLTBg PKS Kelapa Sawit; | E35: Esensial | G35: =VLOOKUP(Table1[[#This Row],[kbli5]],data_versi1!$B$2:$D$101,3, FALSE) -> #N/A | H35: =IF(Table1[[#This Row],[contoh_usaha]]=Table1[[#This Row],[versi 1]],TRUE,FALSE) -> #N/A | I35: D
A36: 35131 | B36: =VLOOKUP(Table1[[#This Row],[kbli5]],master!$A$2:$B$1560,2,FALSE) -> AKTIVITAS PENYALURAN TENAGA LISTRIK | C36: PT PLN UID Riau dan Kepulauan Riau; UPT Transmisi Pekanbaru; Gardu Induk Tenayan Raya; jaringan distribusi listrik PLN; | E36: Esensial | G36: =VLOOKUP(Table1[[#This Row],[kbli5]],data_versi1!$B$2:$D$101,3, FALSE) -> #N/A | H36: =IF(Table1[[#This Row],[contoh_usaha]]=Table1[[#This Row],[versi 1]],TRUE,FALSE) -> #N/A | I36: D
A37: 35132 | B37: =VLOOKUP(Table1[[#This Row],[kbli5]],master!$A$2:$B$1560,2,FALSE) -> AKTIVITAS PENYIMPANAN TENAGA LISTRIK | C37: Aktivitas penyimpanan tenaga listrik; perusahaan yang mengoperasikan fasilitas penyimpanan energi sebagai penunjang internal (PHR, RAPP, IKPP, PLN); | E37: Potensial | G37: =VLOOKUP(Table1[[#This Row],[kbli5]],data_versi1!$B$2:$D$101,3, FALSE) -> #N/A | H37: =IF(Table1[[#This Row],[contoh_usaha]]=Table1[[#This Row],[versi 1]],TRUE,FALSE) -> #N/A | I37: D
A38: 35133 | B38: =VLOOKUP(Table1[[#This Row],[kbli5]],master!$A$2:$B$1560,2,FALSE) -> PENGOPERASIAN FASILITAS ATAU STASIUN PENGISIAN DAYA UNTUK | C38: SPKLU; pengisian daya; kendaraan listrik; | E38: Potensial | G38: =VLOOKUP(Table1[[#This Row],[kbli5]],data_versi1!$B$2:$D$101,3, FALSE) -> #N/A | H38: =IF(Table1[[#This Row],[contoh_usaha]]=Table1[[#This Row],[versi 1]],TRUE,FALSE) -> #N/A | I38: D
A39: 35140 | B39: =VLOOKUP(Table1[[#This Row],[kbli5]],master!$A$2:$B$1560,2,FALSE) -> PENYEDIAAN TENAGA LISTRIK DALAM SATU KESATUAN USAHA | C39: PT RAPP; PT Indah Kiat; SPKLU terintegrasi dengan pembangkit; | E39: Potensial | G39: =VLOOKUP(Table1[[#This Row],[kbli5]],data_versi1!$B$2:$D$101,3, FALSE) -> #N/A | H39: =IF(Table1[[#This Row],[contoh_usaha]]=Table1[[#This Row],[versi 1]],TRUE,FALSE) -> #N/A | I39: D
A40: 35151 | B40: =VLOOKUP(Table1[[#This Row],[kbli5]],master!$A$2:$B$1560,2,FALSE) -> PENGOPERASIAN INSTALASI PENYEDIAAN TENAGA LISTRIK | C40: Operator instalasi listrik; Jasa Operator & Perawatan Genset; jasa operasi PLTU Tenayan Raya; jasa pengoperasian gardu induk PLN; | E40: Potensial | G40: =VLOOKUP(Table1[[#This Row],[kbli5]],data_versi1!$B$2:$D$101,3, FALSE) -> #N/A | H40: =IF(Table1[[#This Row],[contoh_usaha]]=Table1[[#This Row],[versi 1]],TRUE,FALSE) -> #N/A | I40: D
A41: 35152 | B41: =VLOOKUP(Table1[[#This Row],[kbli5]],master!$A$2:$B$1560,2,FALSE) -> PENGOPERASIAN INSTALASI PEMANFAATAN TENAGA LISTRIK | C41: Jasa teknisi listrik panggilan; Pengelola instalasi listrik gedung/mal; Jasa perawatan & pengoperasian AC; | E41: Umum Ditemukan | G41: =VLOOKUP(Table1[[#This Row],[kbli5]],data_versi1!$B$2:$D$101,3, FALSE) -> #N/A | H41: =IF(Table1[[#This Row],[contoh_usaha]]=Table1[[#This Row],[versi 1]],TRUE,FALSE) -> #N/A | I41: D
A42: 35159 | B42: =VLOOKUP(Table1[[#This Row],[kbli5]],master!$A$2:$B$1560,2,FALSE) -> AKTIVITAS PENUNJANG TENAGA LISTRIK LAINNYA | C42: Aktv penunjang tenaga listrik lainnya; Jasa pencatatan meter listrik;Biro Jasa; Pengurusan Listrik; penagihan rekening listrik; | E42: Potensial | G42: =VLOOKUP(Table1[[#This Row],[kbli5]],data_versi1!$B$2:$D$101,3, FALSE) -> #N/A | H42: =IF(Table1[[#This Row],[contoh_usaha]]=Table1[[#This Row],[versi 1]],TRUE,FALSE) -> #N/A | I42: D
A43: 35201 | B43: =VLOOKUP(Table1[[#This Row],[kbli5]],master!$A$2:$B$1560,2,FALSE) -> PRODUKSI GAS ALAM DAN BUATAN | C43: Produksi gas alam & buatan; PT Pertamina Hulu Rokan; fasilitas pengolahan gas alam; instalasi biogas pabrik kelapa sawit; Produksi LPG/biogas/hidrogen untuk bahan bakar; | E43: Esensial | G43: =VLOOKUP(Table1[[#This Row],[kbli5]],data_versi1!$B$2:$D$101,3, FALSE) -> #N/A | H43: =IF(Table1[[#This Row],[contoh_usaha]]=Table1[[#This Row],[versi 1]],TRUE,FALSE) -> #N/A | I43: D
A44: 35202 | B44: =VLOOKUP(Table1[[#This Row],[kbli5]],master!$A$2:$B$1560,2,FALSE) -> DISTRIBUSI GAS ALAM DAN BUATAN MELALUI JARINGAN | C44: Distribusi gas alam & buatan; Jaringan Gas Kota (Jargas) PGN Pekanbaru; distribusi gas bumi ke rumah tangga; penyaluran gas pipa ke pelanggan industri dan komersial; | E44: Esensial | G44: =VLOOKUP(Table1[[#This Row],[kbli5]],data_versi1!$B$2:$D$101,3, FALSE) -> #N/A | H44: =IF(Table1[[#This Row],[contoh_usaha]]=Table1[[#This Row],[versi 1]],TRUE,FALSE) -> #N/A | I44: D
A45: 35301 | B45: =VLOOKUP(Table1[[#This Row],[kbli5]],master!$A$2:$B$1560,2,FALSE) -> PENGADAAN UAP/AIR PANAS DAN UDARA DINGIN | C45: Pengadaan uap/air panas & udara dingin; Penyedia steam PT RAPP; Utilitas uap PT Indah Kiat Perawang; Boiler pabrik kelapa sawit; | E45: Potensial | G45: =VLOOKUP(Table1[[#This Row],[kbli5]],data_versi1!$B$2:$D$101,3, FALSE) -> #N/A | H45: =IF(Table1[[#This Row],[contoh_usaha]]=Table1[[#This Row],[versi 1]],TRUE,FALSE) -> #N/A | I45: D
... A48: 35402 | B48: =VLOOKUP(Table1[[#This Row],[kbli5]],master!$A$2:$B$1560,2,FALSE) -> AKTIVITAS BROKER DAN AGEN PENJUALAN GAS ALAM | C48: Aktv broker & agen penjualan gas alam; Agen penjualan gas LPG; Agen pemasaran gas bumi untuk industri; broker perdagangan gas alam; | E48: Umum Ditemukan | G48: =VLOOKUP(Table1[[#This Row],[kbli5]],data_versi1!$B$2:$D$101,3, FALSE) -> #N/A | H48: =IF(Table1[[#This Row],[contoh_usaha]]=Table1[[#This Row],[versi 1]],TRUE,FALSE) -> #N/A | I48: D
A49: 36001 | B49: =VLOOKUP(Table1[[#This Row],[kbli5]],master!$A$2:$B$1560,2,FALSE) -> PENGOLAHAN DAN PENYEDIAAN AIR MINUM | C49: PDAM; Perumda air minum tirta siak; UPT pengelolaan air minum; | E49: Esensial | F49: Ekonomi Hijau; | G49: =VLOOKUP(Table1[[#This Row],[kbli5]],data_versi1!$B$2:$D$101,3, FALSE) -> PDAM; Perumda air minum tirta siak; UPT pengelolaan air minum; | H49: =IF(Table1[[#This Row],[contoh_usaha]]=Table1[[#This Row],[versi 1]],TRUE,FALSE) -> TRUE | I49: E
A50: 36002 | B50: =VLOOKUP(Table1[[#This Row],[kbli5]],master!$A$2:$B$1560,2,FALSE) -> PENAMPUNGAN DAN PENYEDIAAN AIR BAKU | C50: Pengelola waduk air baku; SPAM Durolis Dumai; Pengelolaan air baku waduk koto panjang; | E50: Esensial | F50: Ekonomi Hijau; | G50: =VLOOKUP(Table1[[#This Row],[kbli5]],data_versi1!$B$2:$D$101,3, FALSE) -> Pengelola waduk air baku; SPAM Durolis Dumai; Pengelolaan air baku waduk koto panjang; | H50: =IF(Table1[[#This Row],[contoh_usaha]]=Table1[[#This Row],[versi 1]],TRUE,FALSE) -> TRUE | I50: E
A51: 36003 | B51: =VLOOKUP(Table1[[#This Row],[kbli5]],master!$A$2:$B$1560,2,FALSE) -> AKTIVITAS PENUNJANG PENYEDIAAN AIR | C51: Pedagang air keliling/pikulan/mobil tangki; Jasa mobil tangki air bersih; penyewaan jaringan distribusi air; | E51: Umum Ditemukan | F51: Ekonomi Hijau; | G51: =VLOOKUP(Table1[[#This Row],[kbli5]],data_versi1!$B$2:$D$101,3, FALSE) -> Pedagang air keliling/pikulan/mobil tangki; Jasa mobil tangki air bersih; penyewaan jaringan distribusi air; | H51: =IF(Table1[[#This Row],[contoh_usaha]]=Table1[[#This Row],[versi 1]],TRUE,FALSE) -> TRUE | I51: E
A52: 37001 | B52: =VLOOKUP(Table1[[#This Row],[kbli5]],master!$A$2:$B$1560,2,FALSE) -> PENGUMPULAN AIR LIMBAH | C52: Pengelola saluran limbah; Jasa sedot WC; Jasa penyedotan tangki septik; | E52: Umum Ditemukan | F52: Ekonomi Hijau; | G52: =VLOOKUP(Table1[[#This Row],[kbli5]],data_versi1!$B$2:$D$101,3, FALSE) -> Pengelola saluran limbah; Jasa sedot WC; Jasa penyedotan tangki septik; | H52: =IF(Table1[[#This Row],[contoh_usaha]]=Table1[[#This Row],[versi 1]],TRUE,FALSE) -> TRUE | I52: E
A53: 38110 | B53: =VLOOKUP(Table1[[#This Row],[kbli5]],master!$A$2:$B$1560,2,FALSE) -> PENGUMPULAN LIMBAH ATAU SAMPAH TIDAK BERBAHAYA | C53: Bank sampah; Jasa angkut sampah rumah tangga; Pengelola TPS; Unit pengangkutan sampah DLHK; | E53: Umum Ditemukan | F53: Ekonomi Hijau; | G53: =VLOOKUP(Table1[[#This Row],[kbli5]],data_versi1!$B$2:$D$101,3, FALSE) -> Bank sampah; Jasa angkut sampah rumah tangga; Pengelola TPS; Unit pengangkutan sampah DLHK; | H53: =IF(Table1[[#This Row],[contoh_usaha]]=Table1[[#This Row],[versi 1]],TRUE,FALSE) -> TRUE | I53: E
A54: 38212 | B54: =VLOOKUP(Table1[[#This Row],[kbli5]],master!$A$2:$B$1560,2,FALSE) -> PRODUKSI KOMPOS SAMPAH ORGANIK | C54: Rumah Kompos DLHK; unit pengolahan kompos sampah pasar; pengolahan kompos dari tandan kosong kelapa sawit; bank sampah penghasil kompos; | E54: Umum Ditemukan | F54: Ekonomi Hijau; | G54: =VLOOKUP(Table1[[#This Row],[kbli5]],data_versi1!$B$2:$D$101,3, FALSE) -> Rumah Kompos DLHK; unit pengolahan kompos sampah pasar; pengolahan kompos dari tandan kosong kelapa sawit; bank sampah penghasil kompos; | H54: =IF(Table1[[#This Row],[contoh_usaha]]=Table1[[#This Row],[versi 1]],TRUE,FALSE) -> TRUE | I54: E
...

Sheet daricanva
A1: [D] 35111 | B1: PLTU Tenayan Pekanbaru; PLTGU Riau Pekanbaru; PLTMG Balai Pungut Bengkalis; PLTMG Teluk Lembu; Turbin Gas PHR; PLTU Batu Bara Industri; | C1: Esensial
A3: [D] 35120 | B3: PLTA Koto Panjang Kampar; Pembangkit Biomassa PT RAPP & PT IKPP; PLTBg PKS Kelapa Sawit; | C3: Esensial
A5: [D] 35131 | B5: PT PLN UID Riau dan Kepulauan Riau; UPT Transmisi Pekanbaru; Gardu Induk Tenayan Raya; jaringan distribusi listrik PLN; | C5: Esensial
A7: [D] 35201 | B7: Produksi gas alam & buatan; PT Pertamina Hulu Rokan; fasilitas pengolahan gas alam; instalasi biogas pabrik kelapa sawit; Produksi LPG/biogas/hidrogen untuk bahan bakar; | C7: Esensial
A9: [D] 35202 | B9: Distribusi gas alam & buatan; Jaringan Gas Kota (Jargas) PGN Pekanbaru; distribusi gas bumi ke rumah tangga; penyaluran gas pipa ke pelanggan industri dan komersial; | C9: Esensial
A11: [E] 36001♻️ | B11: PDAM; Perumda air minum tirta siak; UPT pengelolaan air minum; | C11: Esensial
A13: [E] 36002♻️ | B13: Pengelola waduk air baku; SPAM Durolis Dumai; Pengelolaan air baku waduk koto panjang; | C13: Esensial
A15: [E] 38219 ♻️ | B15: Tempat pembuangan akhir (TPA); Pengelola landfill sampah perkotaan; fasilitas pemusnahan sampah non; B3; | C15: Esensial
A17: [ I ] 55101 🌐♻️ | B17: Hotel Btg 5; Hotel internasional berbintang lima (misalnya jaringan hotel global); Resort mewah dengan standar bintang lima; Labersa hotel; Araduta hotel; | C17: Esensial
A19: [ I ] 55102 | B19: Hotel Btg 4; Premiere; Fox; Zuri PKU & Dumai; Asnof; | C19: Esensial
A21: [ I ] 55103 | B21: Hotel Btg 3; Swiss Bellin SKA; Furaya; Dafam; | C21: Esensial
A23: [ I ] 55104 | B23: Hotel Btg 2; | C23: Esensial
... A283: [T] 96900 | B283: Jasa Lainnya; penitipan & perawatan hewan; biro jodoh; ramalasan; jasa valet parking (biasanya di hotel berbintang); photobox; penampungan hewan (saung kucing, rumah kucing); seniman tato; jasa pemasangan hena; Event Organizer (EO) acara pribadi (wedding organizer, pesta ualng tahun); | C283: Umum Ditemukan
A285: [D] 35132 | B285: Aktivitas penyimpanan tenaga listrik; perusahaan yang mengoperasikan fasilitas penyimpanan energi sebagai penunjang internal (PHR, RAPP, IKPP, PLN);
